[2021-07-27 09:16:33,781] [base.py:152] [base:get_response] [WARNING]- Not Found: /
[2021-07-27 09:16:33,782] [basehttp.py:124] [basehttp:log_message] [WARNING]- "GET / HTTP/1.1" 404 2122
[2021-07-27 09:17:01,103] [basehttp.py:124] [basehttp:log_message] [INFO]- "GET / HTTP/1.1" 200 11290
[2021-07-27 09:19:58,868] [basehttp.py:124] [basehttp:log_message] [INFO]- "GET / HTTP/1.1" 200 11480
[2021-07-27 09:21:34,848] [basehttp.py:124] [basehttp:log_message] [INFO]- "GET / HTTP/1.1" 200 11445
[2021-07-27 09:22:02,105] [basehttp.py:124] [basehttp:log_message] [INFO]- "GET / HTTP/1.1" 200 11447
[2021-07-27 09:31:08,209] [basehttp.py:124] [basehttp:log_message] [INFO]- "GET / HTTP/1.1" 200 11666
[2021-07-27 09:31:12,779] [basehttp.py:124] [basehttp:log_message] [INFO]- "GET / HTTP/1.1" 200 11666
[2021-07-27 09:36:44,967] [basehttp.py:124] [basehttp:log_message] [INFO]- "GET / HTTP/1.1" 200 16486
[2021-07-27 09:39:26,993] [basehttp.py:124] [basehttp:log_message] [INFO]- "GET / HTTP/1.1" 200 21204
[2021-07-27 09:58:37,003] [basehttp.py:124] [basehttp:log_message] [INFO]- "GET / HTTP/1.1" 200 24531
[2021-07-27 09:59:42,050] [basehttp.py:124] [basehttp:log_message] [INFO]- "GET / HTTP/1.1" 200 24352
[2021-07-27 10:00:08,955] [basehttp.py:124] [basehttp:log_message] [INFO]- "GET / HTTP/1.1" 200 24352
[2021-07-27 10:00:44,541] [basehttp.py:124] [basehttp:log_message] [INFO]- "GET / HTTP/1.1" 200 24319
[2021-07-27 10:06:57,515] [basehttp.py:124] [basehttp:log_message] [INFO]- "GET / HTTP/1.1" 200 27462
[2021-07-27 10:07:42,542] [basehttp.py:124] [basehttp:log_message] [INFO]- "GET / HTTP/1.1" 200 27888
[2021-07-27 10:46:09,693] [exception.py:135] [exception:handle_uncaught_exception] [ERROR]- Internal Server Error: /
Traceback (most recent call last):
  File "D:\Software\python\lib\site-packages\pandas\core\indexes\base.py", line 2898, in get_loc
    return self._engine.get_loc(casted_key)
  File "pandas\_libs\index.pyx", line 70, in pandas._libs.index.IndexEngine.get_loc
  File "pandas\_libs\index.pyx", line 101, in pandas._libs.index.IndexEngine.get_loc
  File "pandas\_libs\hashtable_class_helper.pxi", line 1675, in pandas._libs.hashtable.PyObjectHashTable.get_item
  File "pandas\_libs\hashtable_class_helper.pxi", line 1683, in pandas._libs.hashtable.PyObjectHashTable.get_item
KeyError: 'tenDayPm25'

The above exception was the direct cause of the following exception:

Traceback (most recent call last):
  File "D:\Software\python\lib\site-packages\django\core\handlers\exception.py", line 41, in inner
    response = get_response(request)
  File "D:\Software\python\lib\site-packages\django\core\handlers\base.py", line 187, in _get_response
    response = self.process_exception_by_middleware(e, request)
  File "D:\Software\python\lib\site-packages\django\core\handlers\base.py", line 185, in _get_response
    response = wrapped_callback(request, *callback_args, **callback_kwargs)
  File "D:\Personal\Project\weatherAnalysis\weatherCrawler\dashboard.py", line 64, in days_show
    daysData = getDaysData(data)
  File "D:\Personal\Project\weatherAnalysis\weatherCrawler\dashboard.py", line 29, in __init__
    self.tenDayPm25 = self.data['tenDayPm25'].tolist()
  File "D:\Software\python\lib\site-packages\pandas\core\frame.py", line 2906, in __getitem__
    indexer = self.columns.get_loc(key)
  File "D:\Software\python\lib\site-packages\pandas\core\indexes\base.py", line 2900, in get_loc
    raise KeyError(key) from err
KeyError: 'tenDayPm25'
[2021-07-27 10:46:09,863] [basehttp.py:124] [basehttp:log_message] [ERROR]- "GET / HTTP/1.1" 500 93326
[2021-07-27 10:47:41,131] [exception.py:135] [exception:handle_uncaught_exception] [ERROR]- Internal Server Error: /
Traceback (most recent call last):
  File "D:\Software\python\lib\site-packages\django\core\handlers\exception.py", line 41, in inner
    response = get_response(request)
  File "D:\Software\python\lib\site-packages\django\core\handlers\base.py", line 187, in _get_response
    response = self.process_exception_by_middleware(e, request)
  File "D:\Software\python\lib\site-packages\django\core\handlers\base.py", line 185, in _get_response
    response = wrapped_callback(request, *callback_args, **callback_kwargs)
  File "D:\Personal\Project\weatherAnalysis\weatherCrawler\dashboard.py", line 84, in days_show
    .add_yaxis("空气质量指数", daysData.tenDayAqiindex())
TypeError: 'list' object is not callable
[2021-07-27 10:47:41,184] [basehttp.py:124] [basehttp:log_message] [ERROR]- "GET / HTTP/1.1" 500 70180
[2021-07-27 10:48:11,575] [basehttp.py:124] [basehttp:log_message] [INFO]- "GET / HTTP/1.1" 200 27876
[2021-07-27 10:51:18,045] [basehttp.py:124] [basehttp:log_message] [INFO]- "GET / HTTP/1.1" 200 27884
[2021-07-27 11:00:34,276] [exception.py:135] [exception:handle_uncaught_exception] [ERROR]- Internal Server Error: /
Traceback (most recent call last):
  File "D:\Software\python\lib\site-packages\django\core\handlers\exception.py", line 41, in inner
    response = get_response(request)
  File "D:\Software\python\lib\site-packages\django\core\handlers\base.py", line 187, in _get_response
    response = self.process_exception_by_middleware(e, request)
  File "D:\Software\python\lib\site-packages\django\core\handlers\base.py", line 185, in _get_response
    response = wrapped_callback(request, *callback_args, **callback_kwargs)
  File "D:\Personal\Project\weatherAnalysis\weatherCrawler\dashboard.py", line 125, in days_show
    tenDayTempBar, tenDayWindBar,tenDayaqiBar,tenDaypm25Bar,tenDayWeatherPie,tenDayAqiStatusPie))
  File "D:\Software\python\lib\site-packages\pyecharts\charts\composite_charts\page.py", line 71, in add
    for d in c.js_dependencies.items:
AttributeError: 'NoneType' object has no attribute 'js_dependencies'
[2021-07-27 11:00:34,368] [basehttp.py:124] [basehttp:log_message] [ERROR]- "GET / HTTP/1.1" 500 74368
[2021-07-27 11:00:56,239] [exception.py:135] [exception:handle_uncaught_exception] [ERROR]- Internal Server Error: /
Traceback (most recent call last):
  File "D:\Software\python\lib\site-packages\django\core\handlers\exception.py", line 41, in inner
    response = get_response(request)
  File "D:\Software\python\lib\site-packages\django\core\handlers\base.py", line 187, in _get_response
    response = self.process_exception_by_middleware(e, request)
  File "D:\Software\python\lib\site-packages\django\core\handlers\base.py", line 185, in _get_response
    response = wrapped_callback(request, *callback_args, **callback_kwargs)
  File "D:\Personal\Project\weatherAnalysis\weatherCrawler\dashboard.py", line 124, in days_show
    grid = (Page(layout=Page.SimplePageLayout).add(tenDayTempBar, tenDayWindBar,tenDayaqiBar,tenDaypm25Bar,tenDayWeatherPie,tenDayAqiStatusPie))
  File "D:\Software\python\lib\site-packages\pyecharts\charts\composite_charts\page.py", line 71, in add
    for d in c.js_dependencies.items:
AttributeError: 'NoneType' object has no attribute 'js_dependencies'
[2021-07-27 11:00:56,305] [basehttp.py:124] [basehttp:log_message] [ERROR]- "GET / HTTP/1.1" 500 74442
[2021-07-27 11:01:34,919] [basehttp.py:124] [basehttp:log_message] [INFO]- "GET / HTTP/1.1" 200 6047
[2021-07-27 11:01:55,425] [exception.py:135] [exception:handle_uncaught_exception] [ERROR]- Internal Server Error: /
Traceback (most recent call last):
  File "D:\Software\python\lib\site-packages\django\core\handlers\exception.py", line 41, in inner
    response = get_response(request)
  File "D:\Software\python\lib\site-packages\django\core\handlers\base.py", line 187, in _get_response
    response = self.process_exception_by_middleware(e, request)
  File "D:\Software\python\lib\site-packages\django\core\handlers\base.py", line 185, in _get_response
    response = wrapped_callback(request, *callback_args, **callback_kwargs)
  File "D:\Personal\Project\weatherAnalysis\weatherCrawler\dashboard.py", line 125, in days_show
    grid = (Page(layout=Page.SimplePageLayout).add(tenDayTempBar,tenDayWindBar))
  File "D:\Software\python\lib\site-packages\pyecharts\charts\composite_charts\page.py", line 71, in add
    for d in c.js_dependencies.items:
AttributeError: 'NoneType' object has no attribute 'js_dependencies'
[2021-07-27 11:01:55,488] [basehttp.py:124] [basehttp:log_message] [ERROR]- "GET / HTTP/1.1" 500 73673
[2021-07-27 11:02:49,097] [exception.py:135] [exception:handle_uncaught_exception] [ERROR]- Internal Server Error: /
Traceback (most recent call last):
  File "D:\Software\python\lib\site-packages\django\core\handlers\exception.py", line 41, in inner
    response = get_response(request)
  File "D:\Software\python\lib\site-packages\django\core\handlers\base.py", line 187, in _get_response
    response = self.process_exception_by_middleware(e, request)
  File "D:\Software\python\lib\site-packages\django\core\handlers\base.py", line 185, in _get_response
    response = wrapped_callback(request, *callback_args, **callback_kwargs)
  File "D:\Personal\Project\weatherAnalysis\weatherCrawler\dashboard.py", line 125, in days_show
    grid = (Page(layout=Page.SimplePageLayout).add(tenDayTempBar,tenDayaqiBar))
  File "D:\Software\python\lib\site-packages\pyecharts\charts\composite_charts\page.py", line 71, in add
    for d in c.js_dependencies.items:
AttributeError: 'NoneType' object has no attribute 'js_dependencies'
[2021-07-27 11:02:49,167] [basehttp.py:124] [basehttp:log_message] [ERROR]- "GET / HTTP/1.1" 500 73670
[2021-07-27 11:04:10,806] [basehttp.py:124] [basehttp:log_message] [INFO]- "GET / HTTP/1.1" 200 10867
[2021-07-27 11:05:09,868] [basehttp.py:124] [basehttp:log_message] [INFO]- "GET / HTTP/1.1" 200 27884
[2021-07-27 11:05:45,665] [basehttp.py:124] [basehttp:log_message] [INFO]- "GET / HTTP/1.1" 200 27884
[2021-07-27 11:05:47,930] [basehttp.py:124] [basehttp:log_message] [INFO]- "GET / HTTP/1.1" 200 27884
[2021-07-27 11:05:57,914] [exception.py:135] [exception:handle_uncaught_exception] [ERROR]- Internal Server Error: /
Traceback (most recent call last):
  File "D:\Software\python\lib\site-packages\django\core\handlers\exception.py", line 41, in inner
    response = get_response(request)
  File "D:\Software\python\lib\site-packages\django\core\handlers\base.py", line 187, in _get_response
    response = self.process_exception_by_middleware(e, request)
  File "D:\Software\python\lib\site-packages\django\core\handlers\base.py", line 185, in _get_response
    response = wrapped_callback(request, *callback_args, **callback_kwargs)
  File "D:\Personal\Project\weatherAnalysis\weatherCrawler\dashboard.py", line 114, in days_show
    tenDayWeatherPie = daysData.tendWeatherPie()
  File "D:\Personal\Project\weatherAnalysis\weatherCrawler\dashboard.py", line 94, in tendWeatherPie
    .add("", self.getTenWeather())
  File "D:\Software\python\lib\site-packages\pyecharts\charts\basic_charts\pie.py", line 37, in add
    elif isinstance(data_pair[0], opts.PieItem):
TypeError: 'NoneType' object is not subscriptable
[2021-07-27 11:05:57,985] [basehttp.py:124] [basehttp:log_message] [ERROR]- "GET / HTTP/1.1" 500 79780
[2021-07-27 11:06:00,566] [exception.py:135] [exception:handle_uncaught_exception] [ERROR]- Internal Server Error: /
Traceback (most recent call last):
  File "D:\Software\python\lib\site-packages\django\core\handlers\exception.py", line 41, in inner
    response = get_response(request)
  File "D:\Software\python\lib\site-packages\django\core\handlers\base.py", line 187, in _get_response
    response = self.process_exception_by_middleware(e, request)
  File "D:\Software\python\lib\site-packages\django\core\handlers\base.py", line 185, in _get_response
    response = wrapped_callback(request, *callback_args, **callback_kwargs)
  File "D:\Personal\Project\weatherAnalysis\weatherCrawler\dashboard.py", line 114, in days_show
    tenDayWeatherPie = daysData.tendWeatherPie()
  File "D:\Personal\Project\weatherAnalysis\weatherCrawler\dashboard.py", line 94, in tendWeatherPie
    .add("", self.getTenWeather())
  File "D:\Software\python\lib\site-packages\pyecharts\charts\basic_charts\pie.py", line 37, in add
    elif isinstance(data_pair[0], opts.PieItem):
TypeError: 'NoneType' object is not subscriptable
[2021-07-27 11:06:00,615] [basehttp.py:124] [basehttp:log_message] [ERROR]- "GET / HTTP/1.1" 500 79915
[2021-07-27 11:06:33,921] [exception.py:135] [exception:handle_uncaught_exception] [ERROR]- Internal Server Error: /
Traceback (most recent call last):
  File "D:\Software\python\lib\site-packages\django\core\handlers\exception.py", line 41, in inner
    response = get_response(request)
  File "D:\Software\python\lib\site-packages\django\core\handlers\base.py", line 187, in _get_response
    response = self.process_exception_by_middleware(e, request)
  File "D:\Software\python\lib\site-packages\django\core\handlers\base.py", line 185, in _get_response
    response = wrapped_callback(request, *callback_args, **callback_kwargs)
  File "D:\Personal\Project\weatherAnalysis\weatherCrawler\dashboard.py", line 115, in days_show
    tenDayWeatherPie = daysData.tendWeatherPie()
  File "D:\Personal\Project\weatherAnalysis\weatherCrawler\dashboard.py", line 95, in tendWeatherPie
    .add("", self.getTenWeather())
  File "D:\Software\python\lib\site-packages\pyecharts\charts\basic_charts\pie.py", line 37, in add
    elif isinstance(data_pair[0], opts.PieItem):
TypeError: 'NoneType' object is not subscriptable
[2021-07-27 11:06:33,981] [basehttp.py:124] [basehttp:log_message] [ERROR]- "GET / HTTP/1.1" 500 79915
[2021-07-27 11:06:53,732] [basehttp.py:124] [basehttp:log_message] [INFO]- "GET / HTTP/1.1" 200 27884
[2021-07-27 11:08:42,876] [exception.py:135] [exception:handle_uncaught_exception] [ERROR]- Internal Server Error: /
Traceback (most recent call last):
  File "D:\Software\python\lib\site-packages\django\core\handlers\exception.py", line 41, in inner
    response = get_response(request)
  File "D:\Software\python\lib\site-packages\django\core\handlers\base.py", line 187, in _get_response
    response = self.process_exception_by_middleware(e, request)
  File "D:\Software\python\lib\site-packages\django\core\handlers\base.py", line 185, in _get_response
    response = wrapped_callback(request, *callback_args, **callback_kwargs)
  File "D:\Personal\Project\weatherAnalysis\weatherCrawler\dashboard.py", line 127, in days_show
    return HttpResponse(tab.render_embed())
  File "D:\Software\python\lib\site-packages\pyecharts\charts\composite_charts\tab.py", line 53, in render_embed
    return engine.render_embed(self, template_name, env, **kwargs)
  File "D:\Software\python\lib\site-packages\pyecharts\render\engine.py", line 81, in render_embed
    template_name=template_name, chart=chart, **kwargs
  File "D:\Software\python\lib\site-packages\pyecharts\render\engine.py", line 60, in render_chart_to_template
    tpl.render(chart=self.generate_js_link(chart), **kwargs)
  File "D:\Software\python\lib\site-packages\jinja2\environment.py", line 1090, in render
    self.environment.handle_exception()
  File "D:\Software\python\lib\site-packages\jinja2\environment.py", line 832, in handle_exception
    reraise(*rewrite_traceback_stack(source=source))
  File "D:\Software\python\lib\site-packages\jinja2\_compat.py", line 28, in reraise
    raise value.with_traceback(tb)
  File "./weatherCrawler/templates\simple_tab.html", line 19, in top-level template code
    {{ macro.render_chart_content(c) }}
  File "D:\Software\python\lib\site-packages\jinja2\runtime.py", line 679, in _invoke
    rv = self._func(*arguments)
  File "./weatherCrawler/templates\macro", line 19, in template
    {% if c.width.endswith('%') %}
  File "D:\Software\python\lib\site-packages\jinja2\environment.py", line 471, in getattr
    return getattr(obj, attribute)
jinja2.exceptions.UndefinedError: 'pyecharts.charts.composite_charts.page.Page object' has no attribute 'width'
[2021-07-27 11:08:42,996] [basehttp.py:124] [basehttp:log_message] [ERROR]- "GET / HTTP/1.1" 500 115116
[2021-07-27 11:09:29,514] [basehttp.py:124] [basehttp:log_message] [INFO]- "GET / HTTP/1.1" 200 27884
[2021-07-27 11:09:59,641] [exception.py:135] [exception:handle_uncaught_exception] [ERROR]- Internal Server Error: /
Traceback (most recent call last):
  File "D:\Software\python\lib\site-packages\django\core\handlers\exception.py", line 41, in inner
    response = get_response(request)
  File "D:\Software\python\lib\site-packages\django\core\handlers\base.py", line 187, in _get_response
    response = self.process_exception_by_middleware(e, request)
  File "D:\Software\python\lib\site-packages\django\core\handlers\base.py", line 185, in _get_response
    response = wrapped_callback(request, *callback_args, **callback_kwargs)
  File "D:\Personal\Project\weatherAnalysis\weatherCrawler\dashboard.py", line 127, in days_show
    return HttpResponse(tab.render_embed())
  File "D:\Software\python\lib\site-packages\pyecharts\charts\composite_charts\tab.py", line 53, in render_embed
    return engine.render_embed(self, template_name, env, **kwargs)
  File "D:\Software\python\lib\site-packages\pyecharts\render\engine.py", line 81, in render_embed
    template_name=template_name, chart=chart, **kwargs
  File "D:\Software\python\lib\site-packages\pyecharts\render\engine.py", line 60, in render_chart_to_template
    tpl.render(chart=self.generate_js_link(chart), **kwargs)
  File "D:\Software\python\lib\site-packages\jinja2\environment.py", line 1090, in render
    self.environment.handle_exception()
  File "D:\Software\python\lib\site-packages\jinja2\environment.py", line 832, in handle_exception
    reraise(*rewrite_traceback_stack(source=source))
  File "D:\Software\python\lib\site-packages\jinja2\_compat.py", line 28, in reraise
    raise value.with_traceback(tb)
  File "./weatherCrawler/templates\simple_tab.html", line 19, in top-level template code
    {{ macro.render_chart_content(c) }}
  File "D:\Software\python\lib\site-packages\jinja2\runtime.py", line 679, in _invoke
    rv = self._func(*arguments)
  File "./weatherCrawler/templates\macro", line 19, in template
    {% if c.width.endswith('%') %}
  File "D:\Software\python\lib\site-packages\jinja2\environment.py", line 471, in getattr
    return getattr(obj, attribute)
jinja2.exceptions.UndefinedError: 'pyecharts.charts.composite_charts.page.Page object' has no attribute 'width'
[2021-07-27 11:09:59,723] [basehttp.py:124] [basehttp:log_message] [ERROR]- "GET / HTTP/1.1" 500 115101
[2021-07-27 13:37:46,660] [basehttp.py:124] [basehttp:log_message] [INFO]- "GET / HTTP/1.1" 200 27884
[2021-07-27 13:37:48,000] [basehttp.py:124] [basehttp:log_message] [INFO]- "GET /favicon.ico HTTP/1.1" 200 27884
[2021-07-27 14:07:56,650] [exception.py:135] [exception:handle_uncaught_exception] [ERROR]- Internal Server Error: /
Traceback (most recent call last):
  File "D:\Software\python\lib\site-packages\django\core\handlers\exception.py", line 41, in inner
    response = get_response(request)
  File "D:\Software\python\lib\site-packages\django\core\handlers\base.py", line 187, in _get_response
    response = self.process_exception_by_middleware(e, request)
  File "D:\Software\python\lib\site-packages\django\core\handlers\base.py", line 185, in _get_response
    response = wrapped_callback(request, *callback_args, **callback_kwargs)
  File "D:\Personal\Project\weatherAnalysis\weatherCrawler\dashboard.py", line 119, in home
    return render(request, 'templates/home.html', context)
  File "D:\Software\python\lib\site-packages\django\shortcuts.py", line 30, in render
    content = loader.render_to_string(template_name, context, request, using=using)
  File "D:\Software\python\lib\site-packages\django\template\loader.py", line 67, in render_to_string
    template = get_template(template_name, using=using)
  File "D:\Software\python\lib\site-packages\django\template\loader.py", line 25, in get_template
    raise TemplateDoesNotExist(template_name, chain=chain)
django.template.exceptions.TemplateDoesNotExist: templates/home.html
[2021-07-27 14:07:56,740] [basehttp.py:124] [basehttp:log_message] [ERROR]- "GET / HTTP/1.1" 500 83377
[2021-07-27 14:07:57,688] [exception.py:135] [exception:handle_uncaught_exception] [ERROR]- Internal Server Error: /favicon.ico
Traceback (most recent call last):
  File "D:\Software\python\lib\site-packages\django\core\handlers\exception.py", line 41, in inner
    response = get_response(request)
  File "D:\Software\python\lib\site-packages\django\core\handlers\base.py", line 187, in _get_response
    response = self.process_exception_by_middleware(e, request)
  File "D:\Software\python\lib\site-packages\django\core\handlers\base.py", line 185, in _get_response
    response = wrapped_callback(request, *callback_args, **callback_kwargs)
  File "D:\Personal\Project\weatherAnalysis\weatherCrawler\dashboard.py", line 119, in home
    return render(request, 'templates/home.html', context)
  File "D:\Software\python\lib\site-packages\django\shortcuts.py", line 30, in render
    content = loader.render_to_string(template_name, context, request, using=using)
  File "D:\Software\python\lib\site-packages\django\template\loader.py", line 67, in render_to_string
    template = get_template(template_name, using=using)
  File "D:\Software\python\lib\site-packages\django\template\loader.py", line 25, in get_template
    raise TemplateDoesNotExist(template_name, chain=chain)
django.template.exceptions.TemplateDoesNotExist: templates/home.html
[2021-07-27 14:07:57,733] [basehttp.py:124] [basehttp:log_message] [ERROR]- "GET /favicon.ico HTTP/1.1" 500 83313
[2021-07-27 14:08:50,242] [basehttp.py:124] [basehttp:log_message] [INFO]- "GET / HTTP/1.1" 200 123
[2021-07-27 14:08:50,918] [basehttp.py:124] [basehttp:log_message] [INFO]- "GET /favicon.ico HTTP/1.1" 200 123
[2021-07-27 14:10:52,928] [exception.py:135] [exception:handle_uncaught_exception] [ERROR]- Internal Server Error: /
Traceback (most recent call last):
  File "D:\Software\python\lib\site-packages\django\core\handlers\exception.py", line 41, in inner
    response = get_response(request)
  File "D:\Software\python\lib\site-packages\django\core\handlers\base.py", line 187, in _get_response
    response = self.process_exception_by_middleware(e, request)
  File "D:\Software\python\lib\site-packages\django\core\handlers\base.py", line 185, in _get_response
    response = wrapped_callback(request, *callback_args, **callback_kwargs)
  File "D:\Personal\Project\weatherAnalysis\weatherCrawler\dashboard.py", line 118, in home
    return render(request, 'home.html', menu)
  File "D:\Software\python\lib\site-packages\django\shortcuts.py", line 30, in render
    content = loader.render_to_string(template_name, context, request, using=using)
  File "D:\Software\python\lib\site-packages\django\template\loader.py", line 68, in render_to_string
    return template.render(context, request)
  File "D:\Software\python\lib\site-packages\django\template\backends\django.py", line 64, in render
    context = make_context(context, request, autoescape=self.backend.engine.autoescape)
  File "D:\Software\python\lib\site-packages\django\template\context.py", line 287, in make_context
    raise TypeError('context must be a dict rather than %s.' % context.__class__.__name__)
TypeError: context must be a dict rather than list.
[2021-07-27 14:10:53,000] [basehttp.py:124] [basehttp:log_message] [ERROR]- "GET / HTTP/1.1" 500 86373
[2021-07-27 14:10:53,933] [exception.py:135] [exception:handle_uncaught_exception] [ERROR]- Internal Server Error: /favicon.ico
Traceback (most recent call last):
  File "D:\Software\python\lib\site-packages\django\core\handlers\exception.py", line 41, in inner
    response = get_response(request)
  File "D:\Software\python\lib\site-packages\django\core\handlers\base.py", line 187, in _get_response
    response = self.process_exception_by_middleware(e, request)
  File "D:\Software\python\lib\site-packages\django\core\handlers\base.py", line 185, in _get_response
    response = wrapped_callback(request, *callback_args, **callback_kwargs)
  File "D:\Personal\Project\weatherAnalysis\weatherCrawler\dashboard.py", line 118, in home
    return render(request, 'home.html', menu)
  File "D:\Software\python\lib\site-packages\django\shortcuts.py", line 30, in render
    content = loader.render_to_string(template_name, context, request, using=using)
  File "D:\Software\python\lib\site-packages\django\template\loader.py", line 68, in render_to_string
    return template.render(context, request)
  File "D:\Software\python\lib\site-packages\django\template\backends\django.py", line 64, in render
    context = make_context(context, request, autoescape=self.backend.engine.autoescape)
  File "D:\Software\python\lib\site-packages\django\template\context.py", line 287, in make_context
    raise TypeError('context must be a dict rather than %s.' % context.__class__.__name__)
TypeError: context must be a dict rather than list.
[2021-07-27 14:10:53,974] [basehttp.py:124] [basehttp:log_message] [ERROR]- "GET /favicon.ico HTTP/1.1" 500 86456
[2021-07-27 14:11:57,505] [basehttp.py:124] [basehttp:log_message] [INFO]- "GET / HTTP/1.1" 200 208
[2021-07-27 14:11:57,885] [basehttp.py:124] [basehttp:log_message] [INFO]- "GET /favicon.ico HTTP/1.1" 200 208
[2021-07-27 14:29:12,011] [basehttp.py:124] [basehttp:log_message] [INFO]- "GET / HTTP/1.1" 200 27884
[2021-07-27 14:29:13,502] [basehttp.py:124] [basehttp:log_message] [INFO]- "GET /favicon.ico HTTP/1.1" 200 27884
[2021-07-27 14:31:26,986] [basehttp.py:124] [basehttp:log_message] [INFO]- "GET / HTTP/1.1" 200 27884
[2021-07-27 14:31:28,199] [basehttp.py:124] [basehttp:log_message] [INFO]- "GET /favicon.ico HTTP/1.1" 200 27884
[2021-07-27 17:46:45,921] [basehttp.py:124] [basehttp:log_message] [INFO]- "GET / HTTP/1.1" 200 27884
[2021-07-27 17:46:48,070] [basehttp.py:124] [basehttp:log_message] [INFO]- "GET /favicon.ico HTTP/1.1" 200 27884
[2021-07-27 17:46:58,071] [basehttp.py:124] [basehttp:log_message] [INFO]- "GET / HTTP/1.1" 200 27884
[2021-07-27 17:46:59,800] [basehttp.py:124] [basehttp:log_message] [INFO]- "GET /favicon.ico HTTP/1.1" 200 27884
