[2021-09-02 09:05:17,855] [basehttp.py:124] [basehttp:log_message] [INFO]- "GET / HTTP/1.1" 200 28032
[2021-09-02 09:05:19,958] [basehttp.py:124] [basehttp:log_message] [INFO]- "GET /favicon.ico HTTP/1.1" 200 28032
[2021-09-02 09:06:19,267] [basehttp.py:124] [basehttp:log_message] [INFO]- "GET /city_weather_analysis HTTP/1.1" 200 28032
[2021-09-02 09:06:21,053] [basehttp.py:124] [basehttp:log_message] [INFO]- "GET /favicon.ico HTTP/1.1" 200 28032
[2021-09-02 09:06:29,601] [exception.py:135] [exception:handle_uncaught_exception] [ERROR]- Internal Server Error: /city_weather_analysis/
Traceback (most recent call last):
  File "D:\Software\python\lib\site-packages\django\core\handlers\exception.py", line 41, in inner
    response = get_response(request)
  File "D:\Software\python\lib\site-packages\django\core\handlers\base.py", line 187, in _get_response
    response = self.process_exception_by_middleware(e, request)
  File "D:\Software\python\lib\site-packages\django\core\handlers\base.py", line 185, in _get_response
    response = wrapped_callback(request, *callback_args, **callback_kwargs)
  File "D:\Personal\Project\weatherAnalysis\weatherCrawler\dashboard.py", line 326, in city_weather_analysis
    grid = (Page(layout=Page.SimplePageLayout).add(zz_17_pie,zz_18_pie,zz_19_pie,zz_20_pie,zz_21_pie))
  File "D:\Software\python\lib\site-packages\pyecharts\charts\composite_charts\page.py", line 71, in add
    for d in c.js_dependencies.items:
AttributeError: 'cityWeatherAnalysis' object has no attribute 'js_dependencies'
[2021-09-02 09:06:29,681] [basehttp.py:124] [basehttp:log_message] [ERROR]- "GET /city_weather_analysis/ HTTP/1.1" 500 93277
[2021-09-02 09:06:30,853] [basehttp.py:124] [basehttp:log_message] [INFO]- "GET /favicon.ico HTTP/1.1" 200 28032
[2021-09-02 09:10:24,424] [basehttp.py:124] [basehttp:log_message] [INFO]- "GET /city_weather_analysis/ HTTP/1.1" 200 18952
[2021-09-02 09:10:25,794] [basehttp.py:124] [basehttp:log_message] [INFO]- "GET /favicon.ico HTTP/1.1" 200 28032
[2021-09-02 09:12:06,966] [basehttp.py:124] [basehttp:log_message] [INFO]- "GET /city_weather_analysis/ HTTP/1.1" 200 18952
[2021-09-02 09:12:08,257] [basehttp.py:124] [basehttp:log_message] [INFO]- "GET /favicon.ico HTTP/1.1" 200 28032
[2021-09-02 09:16:35,115] [basehttp.py:124] [basehttp:log_message] [INFO]- "GET /city_weather_analysis/ HTTP/1.1" 200 18832
[2021-09-02 09:16:36,660] [basehttp.py:124] [basehttp:log_message] [INFO]- "GET /favicon.ico HTTP/1.1" 200 28032
[2021-09-02 09:18:21,256] [basehttp.py:124] [basehttp:log_message] [INFO]- "GET /city_weather_analysis/ HTTP/1.1" 200 18927
[2021-09-02 09:18:22,739] [basehttp.py:124] [basehttp:log_message] [INFO]- "GET /favicon.ico HTTP/1.1" 200 28032
[2021-09-02 09:21:32,770] [basehttp.py:124] [basehttp:log_message] [INFO]- "GET / HTTP/1.1" 200 28032
[2021-09-02 09:21:34,453] [basehttp.py:124] [basehttp:log_message] [INFO]- "GET /favicon.ico HTTP/1.1" 200 28032
[2021-09-02 09:28:00,426] [exception.py:135] [exception:handle_uncaught_exception] [ERROR]- Internal Server Error: /years_show/
Traceback (most recent call last):
  File "D:\Software\python\lib\site-packages\django\core\handlers\exception.py", line 41, in inner
    response = get_response(request)
  File "D:\Software\python\lib\site-packages\django\core\handlers\base.py", line 187, in _get_response
    response = self.process_exception_by_middleware(e, request)
  File "D:\Software\python\lib\site-packages\django\core\handlers\base.py", line 185, in _get_response
    response = wrapped_callback(request, *callback_args, **callback_kwargs)
  File "D:\Personal\Project\weatherAnalysis\weatherCrawler\dashboard.py", line 290, in years_show
    data = DataFrame(data)
  File "D:\Software\python\lib\site-packages\pandas\core\frame.py", line 529, in __init__
    raise ValueError("DataFrame constructor not properly called!")
ValueError: DataFrame constructor not properly called!
[2021-09-02 09:28:00,506] [basehttp.py:124] [basehttp:log_message] [ERROR]- "GET /years_show/ HTTP/1.1" 500 76530
[2021-09-02 09:28:01,736] [basehttp.py:124] [basehttp:log_message] [INFO]- "GET /favicon.ico HTTP/1.1" 200 28032
[2021-09-02 09:28:14,648] [exception.py:135] [exception:handle_uncaught_exception] [ERROR]- Internal Server Error: /months_show/
Traceback (most recent call last):
  File "D:\Software\python\lib\site-packages\django\core\handlers\exception.py", line 41, in inner
    response = get_response(request)
  File "D:\Software\python\lib\site-packages\django\core\handlers\base.py", line 187, in _get_response
    response = self.process_exception_by_middleware(e, request)
  File "D:\Software\python\lib\site-packages\django\core\handlers\base.py", line 185, in _get_response
    response = wrapped_callback(request, *callback_args, **callback_kwargs)
  File "D:\Personal\Project\weatherAnalysis\weatherCrawler\dashboard.py", line 274, in months_show
    data = DataFrame(data)
  File "D:\Software\python\lib\site-packages\pandas\core\frame.py", line 529, in __init__
    raise ValueError("DataFrame constructor not properly called!")
ValueError: DataFrame constructor not properly called!
[2021-09-02 09:28:14,709] [basehttp.py:124] [basehttp:log_message] [ERROR]- "GET /months_show/ HTTP/1.1" 500 76490
[2021-09-02 09:28:15,901] [basehttp.py:124] [basehttp:log_message] [INFO]- "GET /favicon.ico HTTP/1.1" 200 28032
[2021-09-02 09:28:47,026] [exception.py:135] [exception:handle_uncaught_exception] [ERROR]- Internal Server Error: /months_show/
Traceback (most recent call last):
  File "D:\Software\python\lib\site-packages\django\core\handlers\exception.py", line 41, in inner
    response = get_response(request)
  File "D:\Software\python\lib\site-packages\django\core\handlers\base.py", line 187, in _get_response
    response = self.process_exception_by_middleware(e, request)
  File "D:\Software\python\lib\site-packages\django\core\handlers\base.py", line 185, in _get_response
    response = wrapped_callback(request, *callback_args, **callback_kwargs)
  File "D:\Personal\Project\weatherAnalysis\weatherCrawler\dashboard.py", line 274, in months_show
    data = DataFrame(data)
  File "D:\Software\python\lib\site-packages\pandas\core\frame.py", line 529, in __init__
    raise ValueError("DataFrame constructor not properly called!")
ValueError: DataFrame constructor not properly called!
[2021-09-02 09:28:47,126] [basehttp.py:124] [basehttp:log_message] [ERROR]- "GET /months_show/ HTTP/1.1" 500 76490
[2021-09-02 09:28:48,231] [basehttp.py:124] [basehttp:log_message] [INFO]- "GET /favicon.ico HTTP/1.1" 200 28032
[2021-09-02 09:28:49,773] [basehttp.py:124] [basehttp:log_message] [INFO]- "GET /months_show HTTP/1.1" 200 28032
[2021-09-02 09:28:51,464] [basehttp.py:124] [basehttp:log_message] [INFO]- "GET /favicon.ico HTTP/1.1" 200 28032
[2021-09-02 09:29:25,220] [basehttp.py:124] [basehttp:log_message] [INFO]- "GET /months_show HTTP/1.1" 200 28032
[2021-09-02 09:29:26,685] [basehttp.py:124] [basehttp:log_message] [INFO]- "GET /favicon.ico HTTP/1.1" 200 28032
[2021-09-02 09:30:07,862] [basehttp.py:124] [basehttp:log_message] [INFO]- "GET /months_show HTTP/1.1" 200 28032
[2021-09-02 09:30:09,167] [basehttp.py:124] [basehttp:log_message] [INFO]- "GET /favicon.ico HTTP/1.1" 200 28032
[2021-09-02 09:30:15,968] [basehttp.py:124] [basehttp:log_message] [INFO]- "GET /years_show HTTP/1.1" 200 28032
[2021-09-02 09:30:17,495] [basehttp.py:124] [basehttp:log_message] [INFO]- "GET /favicon.ico HTTP/1.1" 200 28032
[2021-09-02 09:30:22,764] [basehttp.py:124] [basehttp:log_message] [INFO]- "GET /years_show HTTP/1.1" 200 28032
[2021-09-02 09:30:23,887] [basehttp.py:124] [basehttp:log_message] [INFO]- "GET /favicon.ico HTTP/1.1" 200 28032
[2021-09-02 09:32:47,483] [basehttp.py:124] [basehttp:log_message] [INFO]- "GET /favicon.ico HTTP/1.1" 200 28032
[2021-09-02 09:32:51,373] [exception.py:135] [exception:handle_uncaught_exception] [ERROR]- Internal Server Error: /years_show/
Traceback (most recent call last):
  File "D:\Software\python\lib\site-packages\django\core\handlers\exception.py", line 41, in inner
    response = get_response(request)
  File "D:\Software\python\lib\site-packages\django\core\handlers\base.py", line 187, in _get_response
    response = self.process_exception_by_middleware(e, request)
  File "D:\Software\python\lib\site-packages\django\core\handlers\base.py", line 185, in _get_response
    response = wrapped_callback(request, *callback_args, **callback_kwargs)
  File "D:\Personal\Project\weatherAnalysis\weatherCrawler\dashboard.py", line 290, in years_show
    data = DataFrame(data)
  File "D:\Software\python\lib\site-packages\pandas\core\frame.py", line 529, in __init__
    raise ValueError("DataFrame constructor not properly called!")
ValueError: DataFrame constructor not properly called!
[2021-09-02 09:32:51,532] [basehttp.py:124] [basehttp:log_message] [ERROR]- "GET /years_show/ HTTP/1.1" 500 76500
[2021-09-02 09:32:52,666] [basehttp.py:124] [basehttp:log_message] [INFO]- "GET /favicon.ico HTTP/1.1" 200 28032
[2021-09-02 09:35:28,658] [exception.py:135] [exception:handle_uncaught_exception] [ERROR]- Internal Server Error: /years_show/
Traceback (most recent call last):
  File "D:\Software\python\lib\site-packages\django\core\handlers\exception.py", line 41, in inner
    response = get_response(request)
  File "D:\Software\python\lib\site-packages\django\core\handlers\base.py", line 187, in _get_response
    response = self.process_exception_by_middleware(e, request)
  File "D:\Software\python\lib\site-packages\django\core\handlers\base.py", line 185, in _get_response
    response = wrapped_callback(request, *callback_args, **callback_kwargs)
  File "D:\Personal\Project\weatherAnalysis\weatherCrawler\dashboard.py", line 290, in years_show
    data = DataFrame(data)
  File "D:\Software\python\lib\site-packages\pandas\core\frame.py", line 529, in __init__
    raise ValueError("DataFrame constructor not properly called!")
ValueError: DataFrame constructor not properly called!
[2021-09-02 09:35:30,010] [basehttp.py:124] [basehttp:log_message] [ERROR]- "GET /years_show/ HTTP/1.1" 500 78820
[2021-09-02 09:35:32,418] [basehttp.py:124] [basehttp:log_message] [INFO]- "GET /favicon.ico HTTP/1.1" 200 28032
[2021-09-02 09:38:58,435] [exception.py:135] [exception:handle_uncaught_exception] [ERROR]- Internal Server Error: /years_show/
Traceback (most recent call last):
  File "D:\Software\python\lib\site-packages\django\core\handlers\exception.py", line 41, in inner
    response = get_response(request)
  File "D:\Software\python\lib\site-packages\django\core\handlers\base.py", line 187, in _get_response
    response = self.process_exception_by_middleware(e, request)
  File "D:\Software\python\lib\site-packages\django\core\handlers\base.py", line 185, in _get_response
    response = wrapped_callback(request, *callback_args, **callback_kwargs)
  File "D:\Personal\Project\weatherAnalysis\weatherCrawler\dashboard.py", line 293, in years_show
    yearsData = getMYData(data,datetype)
  File "D:\Personal\Project\weatherAnalysis\weatherCrawler\dashboard.py", line 155, in __init__
    ['aqi_index', 'aqi_rank', 'pm25', 'daytemp', 'nighttemp', 'daywind', 'nightwind']].astype(int)
  File "D:\Software\python\lib\site-packages\pandas\core\generic.py", line 5548, in astype
    new_data = self._mgr.astype(dtype=dtype, copy=copy, errors=errors,)
  File "D:\Software\python\lib\site-packages\pandas\core\internals\managers.py", line 604, in astype
    return self.apply("astype", dtype=dtype, copy=copy, errors=errors)
  File "D:\Software\python\lib\site-packages\pandas\core\internals\managers.py", line 409, in apply
    applied = getattr(b, f)(**kwargs)
  File "D:\Software\python\lib\site-packages\pandas\core\internals\blocks.py", line 595, in astype
    values = astype_nansafe(vals1d, dtype, copy=True)
  File "D:\Software\python\lib\site-packages\pandas\core\dtypes\cast.py", line 974, in astype_nansafe
    return lib.astype_intsafe(arr.ravel(), dtype).reshape(arr.shape)
  File "pandas\_libs\lib.pyx", line 615, in pandas._libs.lib.astype_intsafe
ValueError: invalid literal for int() with base 10: '风'
[2021-09-02 09:38:58,618] [basehttp.py:124] [basehttp:log_message] [ERROR]- "GET /years_show/ HTTP/1.1" 500 102446
[2021-09-02 09:38:59,395] [basehttp.py:124] [basehttp:log_message] [INFO]- "GET /favicon.ico HTTP/1.1" 200 28032
[2021-09-02 09:41:59,728] [exception.py:135] [exception:handle_uncaught_exception] [ERROR]- Internal Server Error: /years_show/
Traceback (most recent call last):
  File "D:\Software\python\lib\site-packages\django\core\handlers\exception.py", line 41, in inner
    response = get_response(request)
  File "D:\Software\python\lib\site-packages\django\core\handlers\base.py", line 187, in _get_response
    response = self.process_exception_by_middleware(e, request)
  File "D:\Software\python\lib\site-packages\django\core\handlers\base.py", line 185, in _get_response
    response = wrapped_callback(request, *callback_args, **callback_kwargs)
  File "D:\Personal\Project\weatherAnalysis\weatherCrawler\dashboard.py", line 293, in years_show
    yearsData = getMYData(data,datetype)
  File "D:\Personal\Project\weatherAnalysis\weatherCrawler\dashboard.py", line 155, in __init__
    ['aqi_index', 'aqi_rank', 'pm25', 'daytemp', 'nighttemp', 'daywind', 'nightwind']].astype(int)
  File "D:\Software\python\lib\site-packages\pandas\core\generic.py", line 5548, in astype
    new_data = self._mgr.astype(dtype=dtype, copy=copy, errors=errors,)
  File "D:\Software\python\lib\site-packages\pandas\core\internals\managers.py", line 604, in astype
    return self.apply("astype", dtype=dtype, copy=copy, errors=errors)
  File "D:\Software\python\lib\site-packages\pandas\core\internals\managers.py", line 409, in apply
    applied = getattr(b, f)(**kwargs)
  File "D:\Software\python\lib\site-packages\pandas\core\internals\blocks.py", line 595, in astype
    values = astype_nansafe(vals1d, dtype, copy=True)
  File "D:\Software\python\lib\site-packages\pandas\core\dtypes\cast.py", line 974, in astype_nansafe
    return lib.astype_intsafe(arr.ravel(), dtype).reshape(arr.shape)
  File "pandas\_libs\lib.pyx", line 615, in pandas._libs.lib.astype_intsafe
ValueError: invalid literal for int() with base 10: ''
[2021-09-02 09:41:59,912] [basehttp.py:124] [basehttp:log_message] [ERROR]- "GET /years_show/ HTTP/1.1" 500 102502
[2021-09-02 09:42:00,862] [basehttp.py:124] [basehttp:log_message] [INFO]- "GET /favicon.ico HTTP/1.1" 200 28032
[2021-09-02 09:43:00,070] [exception.py:135] [exception:handle_uncaught_exception] [ERROR]- Internal Server Error: /years_show/
Traceback (most recent call last):
  File "D:\Software\python\lib\site-packages\django\core\handlers\exception.py", line 41, in inner
    response = get_response(request)
  File "D:\Software\python\lib\site-packages\django\core\handlers\base.py", line 187, in _get_response
    response = self.process_exception_by_middleware(e, request)
  File "D:\Software\python\lib\site-packages\django\core\handlers\base.py", line 185, in _get_response
    response = wrapped_callback(request, *callback_args, **callback_kwargs)
  File "D:\Personal\Project\weatherAnalysis\weatherCrawler\dashboard.py", line 294, in years_show
    yearsData = getMYData(data,datetype)
  File "D:\Personal\Project\weatherAnalysis\weatherCrawler\dashboard.py", line 156, in __init__
    ['aqi_index', 'aqi_rank', 'pm25', 'daytemp', 'nighttemp', 'daywind', 'nightwind']].astype(int)
  File "D:\Software\python\lib\site-packages\pandas\core\generic.py", line 5548, in astype
    new_data = self._mgr.astype(dtype=dtype, copy=copy, errors=errors,)
  File "D:\Software\python\lib\site-packages\pandas\core\internals\managers.py", line 604, in astype
    return self.apply("astype", dtype=dtype, copy=copy, errors=errors)
  File "D:\Software\python\lib\site-packages\pandas\core\internals\managers.py", line 409, in apply
    applied = getattr(b, f)(**kwargs)
  File "D:\Software\python\lib\site-packages\pandas\core\internals\blocks.py", line 595, in astype
    values = astype_nansafe(vals1d, dtype, copy=True)
  File "D:\Software\python\lib\site-packages\pandas\core\dtypes\cast.py", line 974, in astype_nansafe
    return lib.astype_intsafe(arr.ravel(), dtype).reshape(arr.shape)
  File "pandas\_libs\lib.pyx", line 615, in pandas._libs.lib.astype_intsafe
ValueError: invalid literal for int() with base 10: '风'
[2021-09-02 09:43:00,301] [basehttp.py:124] [basehttp:log_message] [ERROR]- "GET /years_show/ HTTP/1.1" 500 102464
[2021-09-02 09:43:01,335] [basehttp.py:124] [basehttp:log_message] [INFO]- "GET /favicon.ico HTTP/1.1" 200 28032
[2021-09-02 09:54:19,899] [basehttp.py:124] [basehttp:log_message] [INFO]- "GET /years_show/ HTTP/1.1" 200 29248
[2021-09-02 09:54:21,433] [basehttp.py:124] [basehttp:log_message] [INFO]- "GET /favicon.ico HTTP/1.1" 200 28032
[2021-09-02 10:16:48,632] [basehttp.py:124] [basehttp:log_message] [INFO]- "GET /zz_weather_analysis/ HTTP/1.1" 200 23351
[2021-09-02 10:16:50,099] [basehttp.py:124] [basehttp:log_message] [INFO]- "GET /favicon.ico HTTP/1.1" 200 28032
[2021-09-02 10:25:05,544] [exception.py:135] [exception:handle_uncaught_exception] [ERROR]- Internal Server Error: /zz_weather_analysis/
Traceback (most recent call last):
  File "D:\Software\python\lib\site-packages\pandas\core\indexes\base.py", line 2898, in get_loc
    return self._engine.get_loc(casted_key)
  File "pandas\_libs\index.pyx", line 70, in pandas._libs.index.IndexEngine.get_loc
  File "pandas\_libs\index.pyx", line 101, in pandas._libs.index.IndexEngine.get_loc
  File "pandas\_libs\hashtable_class_helper.pxi", line 1675, in pandas._libs.hashtable.PyObjectHashTable.get_item
  File "pandas\_libs\hashtable_class_helper.pxi", line 1683, in pandas._libs.hashtable.PyObjectHashTable.get_item
KeyError: 'aqi_status'

The above exception was the direct cause of the following exception:

Traceback (most recent call last):
  File "D:\Software\python\lib\site-packages\django\core\handlers\exception.py", line 41, in inner
    response = get_response(request)
  File "D:\Software\python\lib\site-packages\django\core\handlers\base.py", line 187, in _get_response
    response = self.process_exception_by_middleware(e, request)
  File "D:\Software\python\lib\site-packages\django\core\handlers\base.py", line 185, in _get_response
    response = wrapped_callback(request, *callback_args, **callback_kwargs)
  File "D:\Personal\Project\weatherAnalysis\weatherCrawler\dashboard.py", line 331, in zz_weather_analysis
    zz_17_pie = cityWeatherAnalysis(zz_17_data).WeatherPie()
  File "D:\Personal\Project\weatherAnalysis\weatherCrawler\dashboard.py", line 241, in __init__
    self.aqi_data = DataFrame(data)['aqi_status'].tolist()
  File "D:\Software\python\lib\site-packages\pandas\core\frame.py", line 2906, in __getitem__
    indexer = self.columns.get_loc(key)
  File "D:\Software\python\lib\site-packages\pandas\core\indexes\base.py", line 2900, in get_loc
    raise KeyError(key) from err
KeyError: 'aqi_status'
[2021-09-02 10:25:05,616] [basehttp.py:124] [basehttp:log_message] [ERROR]- "GET /zz_weather_analysis/ HTTP/1.1" 500 109982
[2021-09-02 10:25:07,372] [basehttp.py:124] [basehttp:log_message] [INFO]- "GET /favicon.ico HTTP/1.1" 200 28032
[2021-09-02 10:26:00,953] [basehttp.py:124] [basehttp:log_message] [INFO]- "GET /zz_weather_analysis/ HTTP/1.1" 200 24151
[2021-09-02 10:26:02,195] [basehttp.py:124] [basehttp:log_message] [INFO]- "GET /favicon.ico HTTP/1.1" 200 28032
[2021-09-02 10:32:40,295] [basehttp.py:124] [basehttp:log_message] [INFO]- "GET /favicon.ico HTTP/1.1" 200 28032
[2021-09-02 10:37:55,606] [basehttp.py:124] [basehttp:log_message] [INFO]- "GET /favicon.ico HTTP/1.1" 200 28032
[2021-09-02 10:37:58,162] [basehttp.py:124] [basehttp:log_message] [INFO]- "GET /zz_weather_analysis/ HTTP/1.1" 200 24005
[2021-09-02 10:37:59,552] [basehttp.py:124] [basehttp:log_message] [INFO]- "GET /favicon.ico HTTP/1.1" 200 28032
[2021-09-02 10:38:23,739] [basehttp.py:124] [basehttp:log_message] [INFO]- "GET /zz_weather_analysis/ HTTP/1.1" 200 24004
[2021-09-02 10:38:24,931] [basehttp.py:124] [basehttp:log_message] [INFO]- "GET /favicon.ico HTTP/1.1" 200 28032
