[2021-07-28 09:53:01,514] [exception.py:135] [exception:handle_uncaught_exception] [ERROR]- Internal Server Error: /
Traceback (most recent call last):
  File "D:\Software\python\lib\site-packages\django\core\handlers\exception.py", line 41, in inner
    response = get_response(request)
  File "D:\Software\python\lib\site-packages\django\core\handlers\base.py", line 187, in _get_response
    response = self.process_exception_by_middleware(e, request)
  File "D:\Software\python\lib\site-packages\django\core\handlers\base.py", line 185, in _get_response
    response = wrapped_callback(request, *callback_args, **callback_kwargs)
  File "D:\Personal\Project\weatherAnalysis\weatherCrawler\dashboard.py", line 132, in days_show
    return HttpResponse(tab.render_embed())
  File "D:\Software\python\lib\site-packages\pyecharts\charts\composite_charts\tab.py", line 53, in render_embed
    return engine.render_embed(self, template_name, env, **kwargs)
  File "D:\Software\python\lib\site-packages\pyecharts\render\engine.py", line 81, in render_embed
    template_name=template_name, chart=chart, **kwargs
  File "D:\Software\python\lib\site-packages\pyecharts\render\engine.py", line 60, in render_chart_to_template
    tpl.render(chart=self.generate_js_link(chart), **kwargs)
  File "D:\Software\python\lib\site-packages\jinja2\environment.py", line 1090, in render
    self.environment.handle_exception()
  File "D:\Software\python\lib\site-packages\jinja2\environment.py", line 832, in handle_exception
    reraise(*rewrite_traceback_stack(source=source))
  File "D:\Software\python\lib\site-packages\jinja2\_compat.py", line 28, in reraise
    raise value.with_traceback(tb)
  File "./weatherCrawler/templates\simple_tab.html", line 19, in top-level template code
    {{ macro.render_chart_content(c) }}
  File "D:\Software\python\lib\site-packages\jinja2\runtime.py", line 679, in _invoke
    rv = self._func(*arguments)
  File "./weatherCrawler/templates\macro", line 19, in template
    {% if c.width.endswith('%') %}
  File "D:\Software\python\lib\site-packages\jinja2\environment.py", line 471, in getattr
    return getattr(obj, attribute)
jinja2.exceptions.UndefinedError: 'pyecharts.charts.composite_charts.page.Page object' has no attribute 'width'
[2021-07-28 09:53:01,636] [basehttp.py:124] [basehttp:log_message] [ERROR]- "GET / HTTP/1.1" 500 114971
[2021-07-28 09:53:02,742] [exception.py:135] [exception:handle_uncaught_exception] [ERROR]- Internal Server Error: /favicon.ico
Traceback (most recent call last):
  File "D:\Software\python\lib\site-packages\django\core\handlers\exception.py", line 41, in inner
    response = get_response(request)
  File "D:\Software\python\lib\site-packages\django\core\handlers\base.py", line 187, in _get_response
    response = self.process_exception_by_middleware(e, request)
  File "D:\Software\python\lib\site-packages\django\core\handlers\base.py", line 185, in _get_response
    response = wrapped_callback(request, *callback_args, **callback_kwargs)
  File "D:\Personal\Project\weatherAnalysis\weatherCrawler\dashboard.py", line 132, in days_show
    return HttpResponse(tab.render_embed())
  File "D:\Software\python\lib\site-packages\pyecharts\charts\composite_charts\tab.py", line 53, in render_embed
    return engine.render_embed(self, template_name, env, **kwargs)
  File "D:\Software\python\lib\site-packages\pyecharts\render\engine.py", line 81, in render_embed
    template_name=template_name, chart=chart, **kwargs
  File "D:\Software\python\lib\site-packages\pyecharts\render\engine.py", line 60, in render_chart_to_template
    tpl.render(chart=self.generate_js_link(chart), **kwargs)
  File "D:\Software\python\lib\site-packages\jinja2\environment.py", line 1090, in render
    self.environment.handle_exception()
  File "D:\Software\python\lib\site-packages\jinja2\environment.py", line 832, in handle_exception
    reraise(*rewrite_traceback_stack(source=source))
  File "D:\Software\python\lib\site-packages\jinja2\_compat.py", line 28, in reraise
    raise value.with_traceback(tb)
  File "./weatherCrawler/templates\simple_tab.html", line 19, in top-level template code
    {{ macro.render_chart_content(c) }}
  File "D:\Software\python\lib\site-packages\jinja2\runtime.py", line 679, in _invoke
    rv = self._func(*arguments)
  File "./weatherCrawler/templates\macro", line 19, in template
    {% if c.width.endswith('%') %}
  File "D:\Software\python\lib\site-packages\jinja2\environment.py", line 471, in getattr
    return getattr(obj, attribute)
jinja2.exceptions.UndefinedError: 'pyecharts.charts.composite_charts.page.Page object' has no attribute 'width'
[2021-07-28 09:53:02,806] [basehttp.py:124] [basehttp:log_message] [ERROR]- "GET /favicon.ico HTTP/1.1" 500 114884
[2021-07-28 09:53:24,491] [basehttp.py:124] [basehttp:log_message] [INFO]- "GET / HTTP/1.1" 200 27884
[2021-07-28 09:53:25,513] [basehttp.py:124] [basehttp:log_message] [INFO]- "GET /favicon.ico HTTP/1.1" 200 27884
